Workbook

Sheet Overview
A1: Exercise PT-P1 - Performance Computations
A3: Student | B3: Carl Angelo Patano
A4: Project name | B4: Exercise PTP1 - Patano
A5: Course | B5: ITC-C508
A6: Exercise | B6: PT-P1: Deep Learning (Neural Networks) - No-Code Text Classification
A7: Domain | B7: Telecommunications customer support
A8: System | B8: Telecom Customer Support Feedback Classifier
A9: Business justification | B9: Complaint and urgent-support volume acts as an early churn-risk signal; automated intent triage routes at-risk subscribers to retention before attrition.
A10: Platform | B10: Machine Learning for Kids (machinelearningforkids.co.uk) - Recognising text
A11: Classes | B11: Positive_Praise | Negative_Complaint | Urgent_Support
A12: Test set size | B12: 12 held-out phrases (11 scored, 1 out-of-vocabulary probe)
A13: Date of experiment | B13: July 27, 2026
A15: EXPERIMENTAL DESIGN - THREE CONTROLLED RUNS
A16: Run | B16: Training split (P/N/U) | C16: Total examples | D16: What changed | E16: Purpose
A17: Phase A | B17: 5 / 5 / 5 | C17: 15 | D17: Platform minimum | E17: Baseline. Establishes failure modes.
A18: Phase B | B18: 10 / 10 / 10 | C18: 30 | D18: Dataset doubled with ordinary domain sentences | E18: Isolates the effect of data VOLUME alone.
A19: Step 5 | B19: 12 / 15 / 13 | C19: 40 | D19: 10 failure-targeted examples (negation, sarcasm, urgency) | E19: Isolates the effect of data REPRESENTATIVENESS.
A21: The same 12 test phrases were used in all three runs, and none of them appears in any training set. This keeps the three runs directly comparable.
A23: HEADLINE RESULT
A24: Phase A accuracy | B24: ='Phase A'!$B$23 -> 0.63636364
A25: Phase B accuracy | B25: ='Phase B'!$B$23 -> 0.72727273
A26: Step 5 accuracy | B26: ='Step 5'!$B$23 -> 0.90909091

Sheet Phase A
A1: Phase A - Baseline
A2: Training split (Pos/Neg/Urg): 5 / 5 / 5 | Total training examples: 15 | Model trained: Mon, July 27, 2026 8:09 PM
A3: 1. TEST SET RESULTS
A4: Test ID | B4: Test Phrase | C4: Test Case Type | D4: Expected Class | E4: Predicted Class | F4: Confidence (%) | G4: Correct (1/0)
A5: T01 | B5: The new router works perfectly, no complaints at all. | C5: A - Clear pattern | D5: Positive_Praise | E5: Positive_Praise | F5: 58 | G5: =IF($D5="N/A","-",IF($D5=$E5,1,0)) -> 1
A6: T02 | B6: Very happy with how fast my concern was handled. | C6: A - Clear pattern | D6: Positive_Praise | E6: Positive_Praise | F6: 83 | G6: =IF($D6="N/A","-",IF($D6=$E6,1,0)) -> 1
A7: T03 | B7: Excellent coverage even in the province, well done. | C7: A - Clear pattern | D7: Positive_Praise | E7: Positive_Praise | F7: 89 | G7: =IF($D7="N/A","-",IF($D7=$E7,1,0)) -> 1
A8: T04 | B8: The connection drops every single evening without fail. | C8: A - Clear pattern | D8: Negative_Complaint | E8: Negative_Complaint | F8: 74 | G8: =IF($D8="N/A","-",IF($D8=$E8,1,0)) -> 1
A9: T05 | B9: I am not satisfied with the quality of service lately. | C9: B - Negation | D9: Negative_Complaint | E9: Positive_Praise | F9: 51 | G9: =IF($D9="N/A","-",IF($D9=$E9,1,0)) -> 0
A10: T06 | B10: Support ticket has been open for a month with no update. | C10: A - Clear pattern | D10: Negative_Complaint | E10: Negative_Complaint | F10: 36 | G10: =IF($D10="N/A","-",IF($D10=$E10,1,0)) -> 1
A11: T07 | B11: No signal at all and I have a client presentation in ten minutes. | C11: B - Boundary overlap | D11: Urgent_Support | E11: Negative_Complaint | F11: 42 | G11: =IF($D11="N/A","-",IF($D11=$E11,1,0)) -> 0
A12: T08 | B12: Immediate help needed, my landline is completely dead. | C12: A - Clear pattern | D12: Urgent_Support | E12: Urgent_Support | F12: 76 | G12: =IF($D12="N/A","-",IF($D12=$E12,1,0)) -> 1
A13: T09 | B13: Please restore my service now, I have already paid in full. | C13: A - Clear pattern | D13: Urgent_Support | E13: Urgent_Support | F13: 71 | G13: =IF($D13="N/A","-",IF($D13=$E13,1,0)) -> 1
A14: T10 | B14: Oh wonderful, another outage right when I need the internet most. | C14: B - Sarcasm | D14: Negative_Complaint | E14: Urgent_Support | F14: 47 | G14: =IF($D14="N/A","-",IF($D14=$E14,1,0)) -> 0
A15: T11 | B15: Fantastic, my bill went up again for absolutely no reason. | C15: B - Sarcasm | D15: Negative_Complaint | E15: Urgent_Support | F15: 51 | G15: =IF($D15="N/A","-",IF($D15=$E15,1,0)) -> 0
A16: T12 | B16: Can I update the email address on my account? | C16: C - Out-of-vocabulary | D16: N/A | E16: Urgent_Support | F16: 6 | G16: =IF($D16="N/A","-",IF($D16=$E16,1,0)) -> -
A17: Note: T12 has no correct class by design (no administrative-inquiry label exists). It is excluded from all accuracy computations and used only as an out-of-vocabulary confidence probe.
A19: 2. OVERALL ACCURACY
A20: Evaluated test cases (T12 excluded) | B20: =COUNTA($D$5:$D$16)-COUNTIF($D$5:$D$16,"N/A") -> 11
A21: Correct predictions | B21: =SUM($G$5:$G$16) -> 7
A22: Incorrect predictions | B22: =$B$20-$B$21 -> 4
A23: Overall Accuracy | B23: =IFERROR($B$21/$B$20,0) -> 0.63636364
A24: Accuracy = Correct predictions / Evaluated test cases
A26: 3. CONFUSION MATRIX
A27: Rows = Actual class | Columns = Predicted class
A28: Actual \ Predicted | B28: Positive_Praise | C28: Negative_Complaint | D28: Urgent_Support | E28: Total Actual
A29: Positive_Praise | B29: =COUNTIFS($D$5:$D$16,$A29,$E$5:$E$16,B$28) -> 3 | C29: =COUNTIFS($D$5:$D$16,$A29,$E$5:$E$16,C$28) -> 0 | D29: =COUNTIFS($D$5:$D$16,$A29,$E$5:$E$16,D$28) -> 0 | E29: =SUM(B29:D29) -> 3
A30: Negative_Complaint | B30: =COUNTIFS($D$5:$D$16,$A30,$E$5:$E$16,B$28) -> 1 | C30: =COUNTIFS($D$5:$D$16,$A30,$E$5:$E$16,C$28) -> 2 | D30: =COUNTIFS($D$5:$D$16,$A30,$E$5:$E$16,D$28) -> 2 | E30: =SUM(B30:D30) -> 5
A31: Urgent_Support | B31: =COUNTIFS($D$5:$D$16,$A31,$E$5:$E$16,B$28) -> 0 | C31: =COUNTIFS($D$5:$D$16,$A31,$E$5:$E$16,C$28) -> 1 | D31: =COUNTIFS($D$5:$D$16,$A31,$E$5:$E$16,D$28) -> 2 | E31: =SUM(B31:D31) -> 3
A32: Total Predicted | B32: =SUM(B29:B31) -> 4 | C32: =SUM(C29:C31) -> 3 | D32: =SUM(D29:D31) -> 4 | E32: =SUM(B32:D32) -> 11
A34: 4. PER-CLASS PERFORMANCE METRICS
A35: Class | B35: TP | C35: FP | D35: FN | E35: Precision | F35: Recall | G35: F1-Score
A36: Positive_Praise | B36: =B29 -> 3 | C36: =SUM(B29:B31)-B29 -> 1 | D36: =SUM(B29:D29)-B29 -> 0 | E36: =IFERROR($B36/($B36+$C36),0) -> 0.75 | F36: =IFERROR($B36/($B36+$D36),0) -> 1 | G36: =IFERROR(2*$E36*$F36/($E36+$F36),0) -> 0.85714286
A37: Negative_Complaint | B37: =C30 -> 2 | C37: =SUM(C29:C31)-C30 -> 1 | D37: =SUM(B30:D30)-C30 -> 3 | E37: =IFERROR($B37/($B37+$C37),0) -> 0.66666667 | F37: =IFERROR($B37/($B37+$D37),0) -> 0.4 | G37: =IFERROR(2*$E37*$F37/($E37+$F37),0) -> 0.5
A38: Urgent_Support | B38: =D31 -> 2 | C38: =SUM(D29:D31)-D31 -> 2 | D38: =SUM(B31:D31)-D31 -> 1 | E38: =IFERROR($B38/($B38+$C38),0) -> 0.5 | F38: =IFERROR($B38/($B38+$D38),0) -> 0.66666667 | G38: =IFERROR(2*$E38*$F38/($E38+$F38),0) -> 0.57142857
A39: Macro Average | B39: =SUM(B36:B38) -> 7 | C39: =SUM(C36:C38) -> 4 | D39: =SUM(D36:D38) -> 4 | E39: =AVERAGE(E36:E38) -> 0.63888889 | F39: =AVERAGE(F36:F38) -> 0.68888889 | G39: =AVERAGE(G36:G38) -> 0.64285714
A40: Precision = TP/(TP+FP) | Recall = TP/(TP+FN) | F1 = 2*(Precision*Recall)/(Precision+Recall)
A42: 5. CONFIDENCE ANALYSIS
A43: Mean confidence - correct predictions | B43: =IFERROR(SUMIF($G$5:$G$16,1,$F$5:$F$16)/COUNTIF($G$5:$G$16,1),0) -> 69.571429
A44: Mean confidence - incorrect predictions | B44: =IFERROR(SUMIF($G$5:$G$16,0,$F$5:$F$16)/COUNTIF($G$5:$G$16,0),0) -> 47.75
...

Sheet Phase B
A1: Phase B - Volume increase
A2: Training split (Pos/Neg/Urg): 10 / 10 / 10 | Total training examples: 30 | Model trained: Mon, July 27, 2026 8:58 PM
A3: 1. TEST SET RESULTS
A4: Test ID | B4: Test Phrase | C4: Test Case Type | D4: Expected Class | E4: Predicted Class | F4: Confidence (%) | G4: Correct (1/0)
A5: T01 | B5: The new router works perfectly, no complaints at all. | C5: A - Clear pattern | D5: Positive_Praise | E5: Positive_Praise | F5: 58 | G5: =IF($D5="N/A","-",IF($D5=$E5,1,0)) -> 1
A6: T02 | B6: Very happy with how fast my concern was handled. | C6: A - Clear pattern | D6: Positive_Praise | E6: Positive_Praise | F6: 97 | G6: =IF($D6="N/A","-",IF($D6=$E6,1,0)) -> 1
A7: T03 | B7: Excellent coverage even in the province, well done. | C7: A - Clear pattern | D7: Positive_Praise | E7: Positive_Praise | F7: 96 | G7: =IF($D7="N/A","-",IF($D7=$E7,1,0)) -> 1
A8: T04 | B8: The connection drops every single evening without fail. | C8: A - Clear pattern | D8: Negative_Complaint | E8: Negative_Complaint | F8: 75 | G8: =IF($D8="N/A","-",IF($D8=$E8,1,0)) -> 1
A9: T05 | B9: I am not satisfied with the quality of service lately. | C9: B - Negation | D9: Negative_Complaint | E9: Positive_Praise | F9: 58 | G9: =IF($D9="N/A","-",IF($D9=$E9,1,0)) -> 0
A10: T06 | B10: Support ticket has been open for a month with no update. | C10: A - Clear pattern | D10: Negative_Complaint | E10: Negative_Complaint | F10: 65 | G10: =IF($D10="N/A","-",IF($D10=$E10,1,0)) -> 1
A11: T07 | B11: No signal at all and I have a client presentation in ten minutes. | C11: B - Boundary overlap | D11: Urgent_Support | E11: Negative_Complaint | F11: 63 | G11: =IF($D11="N/A","-",IF($D11=$E11,1,0)) -> 0
A12: T08 | B12: Immediate help needed, my landline is completely dead. | C12: A - Clear pattern | D12: Urgent_Support | E12: Urgent_Support | F12: 89 | G12: =IF($D12="N/A","-",IF($D12=$E12,1,0)) -> 1
A13: T09 | B13: Please restore my service now, I have already paid in full. | C13: A - Clear pattern | D13: Urgent_Support | E13: Urgent_Support | F13: 88 | G13: =IF($D13="N/A","-",IF($D13=$E13,1,0)) -> 1
A14: T10 | B14: Oh wonderful, another outage right when I need the internet most. | C14: B - Sarcasm | D14: Negative_Complaint | E14: Urgent_Support | F14: 50 | G14: =IF($D14="N/A","-",IF($D14=$E14,1,0)) -> 0
A15: T11 | B15: Fantastic, my bill went up again for absolutely no reason. | C15: B - Sarcasm | D15: Negative_Complaint | E15: Negative_Complaint | F15: 49 | G15: =IF($D15="N/A","-",IF($D15=$E15,1,0)) -> 1
A16: T12 | B16: Can I update the email address on my account? | C16: C - Out-of-vocabulary | D16: N/A | E16: Urgent_Support | F16: 5 | G16: =IF($D16="N/A","-",IF($D16=$E16,1,0)) -> -
A17: Note: T12 has no correct class by design (no administrative-inquiry label exists). It is excluded from all accuracy computations and used only as an out-of-vocabulary confidence probe.
A19: 2. OVERALL ACCURACY
A20: Evaluated test cases (T12 excluded) | B20: =COUNTA($D$5:$D$16)-COUNTIF($D$5:$D$16,"N/A") -> 11
A21: Correct predictions | B21: =SUM($G$5:$G$16) -> 8
A22: Incorrect predictions | B22: =$B$20-$B$21 -> 3
A23: Overall Accuracy | B23: =IFERROR($B$21/$B$20,0) -> 0.72727273
A24: Accuracy = Correct predictions / Evaluated test cases
A26: 3. CONFUSION MATRIX
A27: Rows = Actual class | Columns = Predicted class
A28: Actual \ Predicted | B28: Positive_Praise | C28: Negative_Complaint | D28: Urgent_Support | E28: Total Actual
A29: Positive_Praise | B29: =COUNTIFS($D$5:$D$16,$A29,$E$5:$E$16,B$28) -> 3 | C29: =COUNTIFS($D$5:$D$16,$A29,$E$5:$E$16,C$28) -> 0 | D29: =COUNTIFS($D$5:$D$16,$A29,$E$5:$E$16,D$28) -> 0 | E29: =SUM(B29:D29) -> 3
A30: Negative_Complaint | B30: =COUNTIFS($D$5:$D$16,$A30,$E$5:$E$16,B$28) -> 1 | C30: =COUNTIFS($D$5:$D$16,$A30,$E$5:$E$16,C$28) -> 3 | D30: =COUNTIFS($D$5:$D$16,$A30,$E$5:$E$16,D$28) -> 1 | E30: =SUM(B30:D30) -> 5
A31: Urgent_Support | B31: =COUNTIFS($D$5:$D$16,$A31,$E$5:$E$16,B$28) -> 0 | C31: =COUNTIFS($D$5:$D$16,$A31,$E$5:$E$16,C$28) -> 1 | D31: =COUNTIFS($D$5:$D$16,$A31,$E$5:$E$16,D$28) -> 2 | E31: =SUM(B31:D31) -> 3
A32: Total Predicted | B32: =SUM(B29:B31) -> 4 | C32: =SUM(C29:C31) -> 4 | D32: =SUM(D29:D31) -> 3 | E32: =SUM(B32:D32) -> 11
A34: 4. PER-CLASS PERFORMANCE METRICS
A35: Class | B35: TP | C35: FP | D35: FN | E35: Precision | F35: Recall | G35: F1-Score
A36: Positive_Praise | B36: =B29 -> 3 | C36: =SUM(B29:B31)-B29 -> 1 | D36: =SUM(B29:D29)-B29 -> 0 | E36: =IFERROR($B36/($B36+$C36),0) -> 0.75 | F36: =IFERROR($B36/($B36+$D36),0) -> 1 | G36: =IFERROR(2*$E36*$F36/($E36+$F36),0) -> 0.85714286
A37: Negative_Complaint | B37: =C30 -> 3 | C37: =SUM(C29:C31)-C30 -> 1 | D37: =SUM(B30:D30)-C30 -> 2 | E37: =IFERROR($B37/($B37+$C37),0) -> 0.75 | F37: =IFERROR($B37/($B37+$D37),0) -> 0.6 | G37: =IFERROR(2*$E37*$F37/($E37+$F37),0) -> 0.66666667
A38: Urgent_Support | B38: =D31 -> 2 | C38: =SUM(D29:D31)-D31 -> 1 | D38: =SUM(B31:D31)-D31 -> 1 | E38: =IFERROR($B38/($B38+$C38),0) -> 0.66666667 | F38: =IFERROR($B38/($B38+$D38),0) -> 0.66666667 | G38: =IFERROR(2*$E38*$F38/($E38+$F38),0) -> 0.66666667
A39: Macro Average | B39: =SUM(B36:B38) -> 8 | C39: =SUM(C36:C38) -> 3 | D39: =SUM(D36:D38) -> 3 | E39: =AVERAGE(E36:E38) -> 0.72222222 | F39: =AVERAGE(F36:F38) -> 0.75555556 | G39: =AVERAGE(G36:G38) -> 0.73015873
A40: Precision = TP/(TP+FP) | Recall = TP/(TP+FN) | F1 = 2*(Precision*Recall)/(Precision+Recall)
A42: 5. CONFIDENCE ANALYSIS
A43: Mean confidence - correct predictions | B43: =IFERROR(SUMIF($G$5:$G$16,1,$F$5:$F$16)/COUNTIF($G$5:$G$16,1),0) -> 77.125
A44: Mean confidence - incorrect predictions | B44: =IFERROR(SUMIF($G$5:$G$16,0,$F$5:$F$16)/COUNTIF($G$5:$G$16,0),0) -> 57
...

Sheet Step 5
A1: Step 5 - Targeted refinement
A2: Training split (Pos/Neg/Urg): 12 / 15 / 13 | Total training examples: 40 | Model trained: Mon, July 27, 2026 9:18 PM
A3: 1. TEST SET RESULTS
A4: Test ID | B4: Test Phrase | C4: Test Case Type | D4: Expected Class | E4: Predicted Class | F4: Confidence (%) | G4: Correct (1/0)
A5: T01 | B5: The new router works perfectly, no complaints at all. | C5: A - Clear pattern | D5: Positive_Praise | E5: Positive_Praise | F5: 67 | G5: =IF($D5="N/A","-",IF($D5=$E5,1,0)) -> 1
A6: T02 | B6: Very happy with how fast my concern was handled. | C6: A - Clear pattern | D6: Positive_Praise | E6: Positive_Praise | F6: 97 | G6: =IF($D6="N/A","-",IF($D6=$E6,1,0)) -> 1
A7: T03 | B7: Excellent coverage even in the province, well done. | C7: A - Clear pattern | D7: Positive_Praise | E7: Positive_Praise | F7: 96 | G7: =IF($D7="N/A","-",IF($D7=$E7,1,0)) -> 1
A8: T04 | B8: The connection drops every single evening without fail. | C8: A - Clear pattern | D8: Negative_Complaint | E8: Negative_Complaint | F8: 92 | G8: =IF($D8="N/A","-",IF($D8=$E8,1,0)) -> 1
A9: T05 | B9: I am not satisfied with the quality of service lately. | C9: B - Negation | D9: Negative_Complaint | E9: Negative_Complaint | F9: 92 | G9: =IF($D9="N/A","-",IF($D9=$E9,1,0)) -> 1
A10: T06 | B10: Support ticket has been open for a month with no update. | C10: A - Clear pattern | D10: Negative_Complaint | E10: Negative_Complaint | F10: 69 | G10: =IF($D10="N/A","-",IF($D10=$E10,1,0)) -> 1
A11: T07 | B11: No signal at all and I have a client presentation in ten minutes. | C11: B - Boundary overlap | D11: Urgent_Support | E11: Urgent_Support | F11: 77 | G11: =IF($D11="N/A","-",IF($D11=$E11,1,0)) -> 1
A12: T08 | B12: Immediate help needed, my landline is completely dead. | C12: A - Clear pattern | D12: Urgent_Support | E12: Urgent_Support | F12: 91 | G12: =IF($D12="N/A","-",IF($D12=$E12,1,0)) -> 1
A13: T09 | B13: Please restore my service now, I have already paid in full. | C13: A - Clear pattern | D13: Urgent_Support | E13: Urgent_Support | F13: 88 | G13: =IF($D13="N/A","-",IF($D13=$E13,1,0)) -> 1
A14: T10 | B14: Oh wonderful, another outage right when I need the internet most. | C14: B - Sarcasm | D14: Negative_Complaint | E14: Urgent_Support | F14: 50 | G14: =IF($D14="N/A","-",IF($D14=$E14,1,0)) -> 0
A15: T11 | B15: Fantastic, my bill went up again for absolutely no reason. | C15: B - Sarcasm | D15: Negative_Complaint | E15: Negative_Complaint | F15: 72 | G15: =IF($D15="N/A","-",IF($D15=$E15,1,0)) -> 1
A16: T12 | B16: Can I update the email address on my account? | C16: C - Out-of-vocabulary | D16: N/A | E16: Urgent_Support | F16: 3 | G16: =IF($D16="N/A","-",IF($D16=$E16,1,0)) -> -
A17: Note: T12 has no correct class by design (no administrative-inquiry label exists). It is excluded from all accuracy computations and used only as an out-of-vocabulary confidence probe.
A19: 2. OVERALL ACCURACY
A20: Evaluated test cases (T12 excluded) | B20: =COUNTA($D$5:$D$16)-COUNTIF($D$5:$D$16,"N/A") -> 11
A21: Correct predictions | B21: =SUM($G$5:$G$16) -> 10
A22: Incorrect predictions | B22: =$B$20-$B$21 -> 1
A23: Overall Accuracy | B23: =IFERROR($B$21/$B$20,0) -> 0.90909091
A24: Accuracy = Correct predictions / Evaluated test cases
A26: 3. CONFUSION MATRIX
A27: Rows = Actual class | Columns = Predicted class
A28: Actual \ Predicted | B28: Positive_Praise | C28: Negative_Complaint | D28: Urgent_Support | E28: Total Actual
A29: Positive_Praise | B29: =COUNTIFS($D$5:$D$16,$A29,$E$5:$E$16,B$28) -> 3 | C29: =COUNTIFS($D$5:$D$16,$A29,$E$5:$E$16,C$28) -> 0 | D29: =COUNTIFS($D$5:$D$16,$A29,$E$5:$E$16,D$28) -> 0 | E29: =SUM(B29:D29) -> 3
A30: Negative_Complaint | B30: =COUNTIFS($D$5:$D$16,$A30,$E$5:$E$16,B$28) -> 0 | C30: =COUNTIFS($D$5:$D$16,$A30,$E$5:$E$16,C$28) -> 4 | D30: =COUNTIFS($D$5:$D$16,$A30,$E$5:$E$16,D$28) -> 1 | E30: =SUM(B30:D30) -> 5
A31: Urgent_Support | B31: =COUNTIFS($D$5:$D$16,$A31,$E$5:$E$16,B$28) -> 0 | C31: =COUNTIFS($D$5:$D$16,$A31,$E$5:$E$16,C$28) -> 0 | D31: =COUNTIFS($D$5:$D$16,$A31,$E$5:$E$16,D$28) -> 3 | E31: =SUM(B31:D31) -> 3
A32: Total Predicted | B32: =SUM(B29:B31) -> 3 | C32: =SUM(C29:C31) -> 4 | D32: =SUM(D29:D31) -> 4 | E32: =SUM(B32:D32) -> 11
A34: 4. PER-CLASS PERFORMANCE METRICS
A35: Class | B35: TP | C35: FP | D35: FN | E35: Precision | F35: Recall | G35: F1-Score
A36: Positive_Praise | B36: =B29 -> 3 | C36: =SUM(B29:B31)-B29 -> 0 | D36: =SUM(B29:D29)-B29 -> 0 | E36: =IFERROR($B36/($B36+$C36),0) -> 1 | F36: =IFERROR($B36/($B36+$D36),0) -> 1 | G36: =IFERROR(2*$E36*$F36/($E36+$F36),0) -> 1
A37: Negative_Complaint | B37: =C30 -> 4 | C37: =SUM(C29:C31)-C30 -> 0 | D37: =SUM(B30:D30)-C30 -> 1 | E37: =IFERROR($B37/($B37+$C37),0) -> 1 | F37: =IFERROR($B37/($B37+$D37),0) -> 0.8 | G37: =IFERROR(2*$E37*$F37/($E37+$F37),0) -> 0.88888889
A38: Urgent_Support | B38: =D31 -> 3 | C38: =SUM(D29:D31)-D31 -> 1 | D38: =SUM(B31:D31)-D31 -> 0 | E38: =IFERROR($B38/($B38+$C38),0) -> 0.75 | F38: =IFERROR($B38/($B38+$D38),0) -> 1 | G38: =IFERROR(2*$E38*$F38/($E38+$F38),0) -> 0.85714286
A39: Macro Average | B39: =SUM(B36:B38) -> 10 | C39: =SUM(C36:C38) -> 1 | D39: =SUM(D36:D38) -> 1 | E39: =AVERAGE(E36:E38) -> 0.91666667 | F39: =AVERAGE(F36:F38) -> 0.93333333 | G39: =AVERAGE(G36:G38) -> 0.91534392
A40: Precision = TP/(TP+FP) | Recall = TP/(TP+FN) | F1 = 2*(Precision*Recall)/(Precision+Recall)
A42: 5. CONFIDENCE ANALYSIS
A43: Mean confidence - correct predictions | B43: =IFERROR(SUMIF($G$5:$G$16,1,$F$5:$F$16)/COUNTIF($G$5:$G$16,1),0) -> 84.1
A44: Mean confidence - incorrect predictions | B44: =IFERROR(SUMIF($G$5:$G$16,0,$F$5:$F$16)/COUNTIF($G$5:$G$16,0),0) -> 50
...

Sheet Comparison
A1: Three-Phase Comparison
A3: 1. PER-TEST PREDICTION COMPARISON
A4: Test ID | B4: Test Case Type | C4: Expected Class | D4: Phase A | E4: Phase B | F4: Step 5 | G4: Outcome
A5: T01 | B5: A - Clear pattern | C5: Positive_Praise | D5: Pos 58% | E5: Pos 58% | F5: Pos 67% | G5: Correct throughout
A6: T02 | B6: A - Clear pattern | C6: Positive_Praise | D6: Pos 83% | E6: Pos 97% | F6: Pos 97% | G6: Correct throughout
A7: T03 | B7: A - Clear pattern | C7: Positive_Praise | D7: Pos 89% | E7: Pos 96% | F7: Pos 96% | G7: Correct throughout
A8: T04 | B8: A - Clear pattern | C8: Negative_Complaint | D8: Neg 74% | E8: Neg 75% | F8: Neg 92% | G8: Correct throughout
A9: T05 | B9: B - Negation | C9: Negative_Complaint | D9: Pos 51% | E9: Pos 58% | F9: Neg 92% | G9: FIXED by refinement
A10: T06 | B10: A - Clear pattern | C10: Negative_Complaint | D10: Neg 36% | E10: Neg 65% | F10: Neg 69% | G10: Correct throughout
A11: T07 | B11: B - Boundary overlap | C11: Urgent_Support | D11: Neg 42% | E11: Neg 63% | F11: Urg 77% | G11: FIXED by refinement
A12: T08 | B12: A - Clear pattern | C12: Urgent_Support | D12: Urg 76% | E12: Urg 89% | F12: Urg 91% | G12: Correct throughout
A13: T09 | B13: A - Clear pattern | C13: Urgent_Support | D13: Urg 71% | E13: Urg 88% | F13: Urg 88% | G13: Correct throughout
A14: T10 | B14: B - Sarcasm | C14: Negative_Complaint | D14: Urg 47% | E14: Urg 50% | F14: Urg 50% | G14: Wrong throughout - unresolved
A15: T11 | B15: B - Sarcasm | C15: Negative_Complaint | D15: Urg 51% | E15: Neg 49% | F15: Neg 72% | G15: Fixed at Phase B, held
A16: T12 | B16: C - Out-of-vocabulary | C16: N/A | D16: Urg 6% | E16: Urg 5% | F16: Urg 3% | G16: OOV probe - confidence fell 6% > 5% > 3%
A18: 2. AGGREGATE METRIC PROGRESSION
A19: Metric | B19: Phase A | C19: Phase B | D19: Step 5 | E19: A to B change | F19: B to Step 5 change
A20: Training examples (total) | B20: 15 | C20: 30 | D20: 40 | E20: =$C20-$B20 -> 15 | F20: =$D20-$C20 -> 10
A21: Correct predictions (of 11) | B21: ='Phase A'!$B$21 -> 7 | C21: ='Phase B'!$B$21 -> 8 | D21: ='Step 5'!$B$21 -> 10 | E21: =$C21-$B21 -> 1 | F21: =$D21-$C21 -> 2
A22: Overall Accuracy | B22: ='Phase A'!$B$23 -> 0.63636364 | C22: ='Phase B'!$B$23 -> 0.72727273 | D22: ='Step 5'!$B$23 -> 0.90909091 | E22: =$C22-$B22 -> 0.090909091 | F22: =$D22-$C22 -> 0.18181818
A23: Macro Precision | B23: ='Phase A'!$E$39 -> 0.63888889 | C23: ='Phase B'!$E$39 -> 0.72222222 | D23: ='Step 5'!$E$39 -> 0.91666667 | E23: =$C23-$B23 -> 0.083333333 | F23: =$D23-$C23 -> 0.19444444
A24: Macro Recall | B24: ='Phase A'!$F$39 -> 0.68888889 | C24: ='Phase B'!$F$39 -> 0.75555556 | D24: ='Step 5'!$F$39 -> 0.93333333 | E24: =$C24-$B24 -> 0.066666667 | F24: =$D24-$C24 -> 0.17777778
A25: Macro F1-Score | B25: ='Phase A'!$G$39 -> 0.64285714 | C25: ='Phase B'!$G$39 -> 0.73015873 | D25: ='Step 5'!$G$39 -> 0.91534392 | E25: =$C25-$B25 -> 0.087301587 | F25: =$D25-$C25 -> 0.18518519
A26: Mean confidence - correct | B26: ='Phase A'!$B$43 -> 69.571429 | C26: ='Phase B'!$B$43 -> 77.125 | D26: ='Step 5'!$B$43 -> 84.1 | E26: =$C26-$B26 -> 7.5535714 | F26: =$D26-$C26 -> 6.975
A27: Mean confidence - incorrect | B27: ='Phase A'!$B$44 -> 47.75 | C27: ='Phase B'!$B$44 -> 57 | D27: ='Step 5'!$B$44 -> 50 | E27: =$C27-$B27 -> 9.25 | F27: =$D27-$C27 -> -7
A28: Mean confidence - all cases | B28: ='Phase A'!$B$46 -> 61.636364 | C28: ='Phase B'!$B$46 -> 71.636364 | D28: ='Step 5'!$B$46 -> 81 | E28: =$C28-$B28 -> 10 | F28: =$D28-$C28 -> 9.3636364
A29: Out-of-vocabulary confidence | B29: ='Phase A'!$B$47 -> 6 | C29: ='Phase B'!$B$47 -> 5 | D29: ='Step 5'!$B$47 -> 3 | E29: =$C29-$B29 -> -1 | F29: =$D29-$C29 -> -2
A31: 3. TARGETED-FIX OUTCOMES
A32: Test | B32: Failure mode | C32: Fix applied in Step 5 | D32: Phase A | E32: Phase B | F32: Step 5 | G32: Resolved?
A33: T05 | B33: Negation not represented ('not satisfied' read as praise) | C33: 3 explicit negation examples added to Negative_Complaint | D33: Pos 51% | E33: Pos 58% | F33: Neg 92% | G33: YES
A34: T07 | B34: Negative / Urgent boundary too weak; time pressure ignored | C34: 3 time-pressure urgency examples added to Urgent_Support | D34: Neg 42% | E34: Neg 63% | F34: Urg 77% | G34: YES
A35: T10 | B35: Sarcasm; 'outage' token dominates positive tone marker | C35: 2 sarcastic examples added (dropped call, data depletion) | D35: Urg 47% | E35: Urg 50% | F35: Urg 50% | G35: NO
A36: T11 | B36: Sarcasm; 'Fantastic' misread as praise | C36: 2 sarcastic examples added; billing complaints reinforced | D36: Urg 51% | E36: Neg 49% | F36: Neg 72% | G36: YES
A38: 4. KEY OBSERVATIONS
A39: 1. Doubling the dataset (Phase A to Phase B) raised accuracy by roughly nine percentage points and lifted mean confidence, but it resolved none of the four linguistic failures.
A41: 2. On T05 and T07 the extra volume made the model MORE confident while still wrong (51% to 58%, and 42% to 63%). Volume alone can entrench an error rather than correct it.
A43: 3. Ten failure-targeted examples in Step 5 resolved three of the four failures and lifted accuracy far more than the fifteen untargeted examples added in Phase B.
A45: 4. T10 stayed wrong at exactly 50% across all three runs. The sarcastic examples added concerned dropped calls and data depletion, while T10 concerns an outage - a token strongly bound to Urgent_Support. The fix did not cover the vocabulary that caused the error.
A47: 5. Out-of-vocabulary confidence fell steadily (6% to 5% to 3%). As class boundaries sharpened, the model became more certain that this input belonged to none of them.
A49: 6. In every run, mean confidence on incorrect predictions was lower than on correct ones, so a confidence threshold is a usable production safeguard for routing to a human agent.
